Workbook

Sheet Quotation new
C2: Group Ref. No.: | I2: Arr. Date:(dd/mmm/yy) | J2: 45962 | L2: Exchange rate: | M2: 47.7 | N2: EGP
C3: # PAX of Group: | E3: 1 | I3: Dep. Date:(dd/mmm/yy) | J3: 45962 | L3: Estimate Profit: | N3: EURO
B4: EGYPT TOP LIGHT QUOTATION
B6: ACCOMMODATION | F6: SITES/TRIPS | H6: TRANSFERS | J6: MEALS | L6: SERVICES
B7: NIGHTS | C7: Rate | F7: Items | G7: Rate | H7: Items | I7: Rate | J7: Items | K7: Rate | L7: Items | M7: Rate
C8: in DBL | D8: S. Sup. | E8: SUITE . Sup.
C9: USD | D9: USD | E9: USD | G9: LE | I9: LE | K9: LE | M9: LE | N9: USD
D10: =IF(C10="","",C10*0.7) | G10: =IF(F10=""," ",IF(J$2>=DATE(2025,11,1),VLOOKUP(F10,Sites!$A:$C,3,FALSE),VLOOKUP(F10,Sites!$A:$B,2,FALSE))) | I10: =IF(H10="","",IF(J2<DATE(2025,11,1),IF(E$3<=7,VLOOKUP(H10,Transfers!$A:$D,2,FALSE), IF(E$3<=15,VLOOKUP(H10,Transfers!$A:$D,3,FALSE), VLOOKUP(H10,Transfers!$A:$D,4,FALSE))),IF(E$3<=7,VLOOKUP(H10,Transfers!$E:$H,2,FALSE), IF(E$3<=15,VLOOKUP(H10,Transfers!$E:$H,3,FALSE), VLOOKUP(H10,Transfers!$E:$H,4,FALSE))))) | L10: Guide | M10: =(J3-J2)*2000 -> 0
D11: =IF(C11="","",C11*0.7) | G11: =IF(F11=""," ",IF(J$2>=DATE(2025,11,1),VLOOKUP(F11,Sites!$A:$C,3,FALSE),VLOOKUP(F11,Sites!$A:$B,2,FALSE))) | I11: =IF(H11="","",IF(J3<DATE(2025,11,1),IF(E$3<=7,VLOOKUP(H11,Transfers!$A:$D,2,FALSE), IF(E$3<=15,VLOOKUP(H11,Transfers!$A:$D,3,FALSE), VLOOKUP(H11,Transfers!$A:$D,4,FALSE))),IF(E$3<=7,VLOOKUP(H11,Transfers!$E:$H,2,FALSE), IF(E$3<=15,VLOOKUP(H11,Transfers!$E:$H,3,FALSE), VLOOKUP(H11,Transfers!$E:$H,4,FALSE))))) | L11: Rep | M11: =(J3-J2)*400 -> 0
D12: =IF(C12="","",C12*0.7) | G12: =IF(F12=""," ",IF(J$2>=DATE(2025,11,1),VLOOKUP(F12,Sites!$A:$C,3,FALSE),VLOOKUP(F12,Sites!$A:$B,2,FALSE))) | I12: =IF(H12="","",IF(J4<DATE(2025,11,1),IF(E$3<=7,VLOOKUP(H12,Transfers!$A:$D,2,FALSE), IF(E$3<=15,VLOOKUP(H12,Transfers!$A:$D,3,FALSE), VLOOKUP(H12,Transfers!$A:$D,4,FALSE))),IF(E$3<=7,VLOOKUP(H12,Transfers!$E:$H,2,FALSE), IF(E$3<=15,VLOOKUP(H12,Transfers!$E:$H,3,FALSE), VLOOKUP(H12,Transfers!$E:$H,4,FALSE)))))
D13: =IF(C13="","",C13*0.7) | G13: =IF(F13=""," ",IF(J$2>=DATE(2025,11,1),VLOOKUP(F13,Sites!$A:$C,3,FALSE),VLOOKUP(F13,Sites!$A:$B,2,FALSE))) | I13: =IF(H13="","",IF(J5<DATE(2025,11,1),IF(E$3<=7,VLOOKUP(H13,Transfers!$A:$D,2,FALSE), IF(E$3<=15,VLOOKUP(H13,Transfers!$A:$D,3,FALSE), VLOOKUP(H13,Transfers!$A:$D,4,FALSE))),IF(E$3<=7,VLOOKUP(H13,Transfers!$E:$H,2,FALSE), IF(E$3<=15,VLOOKUP(H13,Transfers!$E:$H,3,FALSE), VLOOKUP(H13,Transfers!$E:$H,4,FALSE)))))
D14: =IF(C14="","",C14*0.7) | G14: =IF(F14=""," ",IF(J$2>=DATE(2025,11,1),VLOOKUP(F14,Sites!$A:$C,3,FALSE),VLOOKUP(F14,Sites!$A:$B,2,FALSE))) | I14: =IF(H14="","",IF(J6<DATE(2025,11,1),IF(E$3<=7,VLOOKUP(H14,Transfers!$A:$D,2,FALSE), IF(E$3<=15,VLOOKUP(H14,Transfers!$A:$D,3,FALSE), VLOOKUP(H14,Transfers!$A:$D,4,FALSE))),IF(E$3<=7,VLOOKUP(H14,Transfers!$E:$H,2,FALSE), IF(E$3<=15,VLOOKUP(H14,Transfers!$E:$H,3,FALSE), VLOOKUP(H14,Transfers!$E:$H,4,FALSE)))))
D15: =IF(C15="","",C15*0.7) | G15: =IF(F15=""," ",IF(J$2>=DATE(2025,11,1),VLOOKUP(F15,Sites!$A:$C,3,FALSE),VLOOKUP(F15,Sites!$A:$B,2,FALSE))) | I15: =IF(H15="","",IF(J7<DATE(2025,11,1),IF(E$3<=7,VLOOKUP(H15,Transfers!$A:$D,2,FALSE), IF(E$3<=15,VLOOKUP(H15,Transfers!$A:$D,3,FALSE), VLOOKUP(H15,Transfers!$A:$D,4,FALSE))),IF(E$3<=7,VLOOKUP(H15,Transfers!$E:$H,2,FALSE), IF(E$3<=15,VLOOKUP(H15,Transfers!$E:$H,3,FALSE), VLOOKUP(H15,Transfers!$E:$H,4,FALSE)))))
D16: =IF(C16="","",C16*0.7) | G16: =IF(F16=""," ",IF(J$2>=DATE(2025,11,1),VLOOKUP(F16,Sites!$A:$C,3,FALSE),VLOOKUP(F16,Sites!$A:$B,2,FALSE))) | I16: =IF(H16="","",IF(J8<DATE(2025,11,1),IF(E$3<=7,VLOOKUP(H16,Transfers!$A:$D,2,FALSE), IF(E$3<=15,VLOOKUP(H16,Transfers!$A:$D,3,FALSE), VLOOKUP(H16,Transfers!$A:$D,4,FALSE))),IF(E$3<=7,VLOOKUP(H16,Transfers!$E:$H,2,FALSE), IF(E$3<=15,VLOOKUP(H16,Transfers!$E:$H,3,FALSE), VLOOKUP(H16,Transfers!$E:$H,4,FALSE)))))
G17: =IF(F17=""," ",IF(J$2>=DATE(2025,11,1),VLOOKUP(F17,Sites!$A:$C,3,FALSE),VLOOKUP(F17,Sites!$A:$B,2,FALSE))) | I17: =IF(H17="","",IF(J9<DATE(2025,11,1),IF(E$3<=7,VLOOKUP(H17,Transfers!$A:$D,2,FALSE), IF(E$3<=15,VLOOKUP(H17,Transfers!$A:$D,3,FALSE), VLOOKUP(H17,Transfers!$A:$D,4,FALSE))),IF(E$3<=7,VLOOKUP(H17,Transfers!$E:$H,2,FALSE), IF(E$3<=15,VLOOKUP(H17,Transfers!$E:$H,3,FALSE), VLOOKUP(H17,Transfers!$E:$H,4,FALSE)))))
G18: =IF(F18=""," ",IF(J$2>=DATE(2025,11,1),VLOOKUP(F18,Sites!$A:$C,3,FALSE),VLOOKUP(F18,Sites!$A:$B,2,FALSE))) | I18: =IF(H18="","",IF(J10<DATE(2025,11,1),IF(E$3<=7,VLOOKUP(H18,Transfers!$A:$D,2,FALSE), IF(E$3<=15,VLOOKUP(H18,Transfers!$A:$D,3,FALSE), VLOOKUP(H18,Transfers!$A:$D,4,FALSE))),IF(E$3<=7,VLOOKUP(H18,Transfers!$E:$H,2,FALSE), IF(E$3<=15,VLOOKUP(H18,Transfers!$E:$H,3,FALSE), VLOOKUP(H18,Transfers!$E:$H,4,FALSE)))))
G19: =IF(F19=""," ",IF(J$2>=DATE(2025,11,1),VLOOKUP(F19,Sites!$A:$C,3,FALSE),VLOOKUP(F19,Sites!$A:$B,2,FALSE))) | I19: =IF(H19="","",IF(J11<DATE(2025,11,1),IF(E$3<=7,VLOOKUP(H19,Transfers!$A:$D,2,FALSE), IF(E$3<=15,VLOOKUP(H19,Transfers!$A:$D,3,FALSE), VLOOKUP(H19,Transfers!$A:$D,4,FALSE))),IF(E$3<=7,VLOOKUP(H19,Transfers!$E:$H,2,FALSE), IF(E$3<=15,VLOOKUP(H19,Transfers!$E:$H,3,FALSE), VLOOKUP(H19,Transfers!$E:$H,4,FALSE)))))
G20: =IF(F20=""," ",IF(J$2>=DATE(2025,11,1),VLOOKUP(F20,Sites!$A:$C,3,FALSE),VLOOKUP(F20,Sites!$A:$B,2,FALSE))) | I20: =IF(H20="","",IF(J12<DATE(2025,11,1),IF(E$3<=7,VLOOKUP(H20,Transfers!$A:$D,2,FALSE), IF(E$3<=15,VLOOKUP(H20,Transfers!$A:$D,3,FALSE), VLOOKUP(H20,Transfers!$A:$D,4,FALSE))),IF(E$3<=7,VLOOKUP(H20,Transfers!$E:$H,2,FALSE), IF(E$3<=15,VLOOKUP(H20,Transfers!$E:$H,3,FALSE), VLOOKUP(H20,Transfers!$E:$H,4,FALSE)))))
G21: =IF(F21=""," ",IF(J$2>=DATE(2025,11,1),VLOOKUP(F21,Sites!$A:$C,3,FALSE),VLOOKUP(F21,Sites!$A:$B,2,FALSE))) | I21: =IF(H21="","",IF(J13<DATE(2025,11,1),IF(E$3<=7,VLOOKUP(H21,Transfers!$A:$D,2,FALSE), IF(E$3<=15,VLOOKUP(H21,Transfers!$A:$D,3,FALSE), VLOOKUP(H21,Transfers!$A:$D,4,FALSE))),IF(E$3<=7,VLOOKUP(H21,Transfers!$E:$H,2,FALSE), IF(E$3<=15,VLOOKUP(H21,Transfers!$E:$H,3,FALSE), VLOOKUP(H21,Transfers!$E:$H,4,FALSE)))))
G22: =IF(F22=""," ",IF(J$2>=DATE(2025,11,1),VLOOKUP(F22,Sites!$A:$C,3,FALSE),VLOOKUP(F22,Sites!$A:$B,2,FALSE))) | I22: =IF(H22="","",IF(J14<DATE(2025,11,1),IF(E$3<=7,VLOOKUP(H22,Transfers!$A:$D,2,FALSE), IF(E$3<=15,VLOOKUP(H22,Transfers!$A:$D,3,FALSE), VLOOKUP(H22,Transfers!$A:$D,4,FALSE))),IF(E$3<=7,VLOOKUP(H22,Transfers!$E:$H,2,FALSE), IF(E$3<=15,VLOOKUP(H22,Transfers!$E:$H,3,FALSE), VLOOKUP(H22,Transfers!$E:$H,4,FALSE)))))
G23: =IF(F23=""," ",IF(J$2>=DATE(2025,11,1),VLOOKUP(F23,Sites!$A:$C,3,FALSE),VLOOKUP(F23,Sites!$A:$B,2,FALSE))) | I23: =IF(H23="","",IF(J15<DATE(2025,11,1),IF(E$3<=7,VLOOKUP(H23,Transfers!$A:$D,2,FALSE), IF(E$3<=15,VLOOKUP(H23,Transfers!$A:$D,3,FALSE), VLOOKUP(H23,Transfers!$A:$D,4,FALSE))),IF(E$3<=7,VLOOKUP(H23,Transfers!$E:$H,2,FALSE), IF(E$3<=15,VLOOKUP(H23,Transfers!$E:$H,3,FALSE), VLOOKUP(H23,Transfers!$E:$H,4,FALSE)))))
G24: =IF(F24=""," ",IF(J$2>=DATE(2025,11,1),VLOOKUP(F24,Sites!$A:$C,3,FALSE),VLOOKUP(F24,Sites!$A:$B,2,FALSE))) | I24: =IF(H24="","",IF(J16<DATE(2025,11,1),IF(E$3<=7,VLOOKUP(H24,Transfers!$A:$D,2,FALSE), IF(E$3<=15,VLOOKUP(H24,Transfers!$A:$D,3,FALSE), VLOOKUP(H24,Transfers!$A:$D,4,FALSE))),IF(E$3<=7,VLOOKUP(H24,Transfers!$E:$H,2,FALSE), IF(E$3<=15,VLOOKUP(H24,Transfers!$E:$H,3,FALSE), VLOOKUP(H24,Transfers!$E:$H,4,FALSE)))))
G25: =IF(F25=""," ",IF(J$2>=DATE(2025,11,1),VLOOKUP(F25,Sites!$A:$C,3,FALSE),VLOOKUP(F25,Sites!$A:$B,2,FALSE))) | I25: =IF(H25="","",IF(J17<DATE(2025,11,1),IF(E$3<=7,VLOOKUP(H25,Transfers!$A:$D,2,FALSE), IF(E$3<=15,VLOOKUP(H25,Transfers!$A:$D,3,FALSE), VLOOKUP(H25,Transfers!$A:$D,4,FALSE))),IF(E$3<=7,VLOOKUP(H25,Transfers!$E:$H,2,FALSE), IF(E$3<=15,VLOOKUP(H25,Transfers!$E:$H,3,FALSE), VLOOKUP(H25,Transfers!$E:$H,4,FALSE)))))
G26: =IF(F26=""," ",IF(J$2>=DATE(2025,11,1),VLOOKUP(F26,Sites!$A:$C,3,FALSE),VLOOKUP(F26,Sites!$A:$B,2,FALSE))) | I26: =IF(H26="","",IF(J18<DATE(2025,11,1),IF(E$3<=7,VLOOKUP(H26,Transfers!$A:$D,2,FALSE), IF(E$3<=15,VLOOKUP(H26,Transfers!$A:$D,3,FALSE), VLOOKUP(H26,Transfers!$A:$D,4,FALSE))),IF(E$3<=7,VLOOKUP(H26,Transfers!$E:$H,2,FALSE), IF(E$3<=15,VLOOKUP(H26,Transfers!$E:$H,3,FALSE), VLOOKUP(H26,Transfers!$E:$H,4,FALSE)))))
G27: =IF(F27=""," ",IF(J$2>=DATE(2025,11,1),VLOOKUP(F27,Sites!$A:$C,3,FALSE),VLOOKUP(F27,Sites!$A:$B,2,FALSE))) | I27: =IF(H27="","",IF(J19<DATE(2025,11,1),IF(E$3<=7,VLOOKUP(H27,Transfers!$A:$D,2,FALSE), IF(E$3<=15,VLOOKUP(H27,Transfers!$A:$D,3,FALSE), VLOOKUP(H27,Transfers!$A:$D,4,FALSE))),IF(E$3<=7,VLOOKUP(H27,Transfers!$E:$H,2,FALSE), IF(E$3<=15,VLOOKUP(H27,Transfers!$E:$H,3,FALSE), VLOOKUP(H27,Transfers!$E:$H,4,FALSE)))))
G28: =IF(F28=""," ",IF(J$2>=DATE(2025,11,1),VLOOKUP(F28,Sites!$A:$C,3,FALSE),VLOOKUP(F28,Sites!$A:$B,2,FALSE))) | I28: =IF(H28="","",IF(J20<DATE(2025,11,1),IF(E$3<=7,VLOOKUP(H28,Transfers!$A:$D,2,FALSE), IF(E$3<=15,VLOOKUP(H28,Transfers!$A:$D,3,FALSE), VLOOKUP(H28,Transfers!$A:$D,4,FALSE))),IF(E$3<=7,VLOOKUP(H28,Transfers!$E:$H,2,FALSE), IF(E$3<=15,VLOOKUP(H28,Transfers!$E:$H,3,FALSE), VLOOKUP(H28,Transfers!$E:$H,4,FALSE)))))
... G38: =IF(F38=""," ",IF(J$2>=DATE(2025,11,1),VLOOKUP(F38,Sites!$A:$C,3,FALSE),VLOOKUP(F38,Sites!$A:$B,2,FALSE))) | I38: =IF(H38="","",IF(J30<DATE(2025,11,1),IF(E$3<=7,VLOOKUP(H38,Transfers!$A:$D,2,FALSE), IF(E$3<=15,VLOOKUP(H38,Transfers!$A:$D,3,FALSE), VLOOKUP(H38,Transfers!$A:$D,4,FALSE))),IF(E$3<=7,VLOOKUP(H38,Transfers!$E:$H,2,FALSE), IF(E$3<=15,VLOOKUP(H38,Transfers!$E:$H,3,FALSE), VLOOKUP(H38,Transfers!$E:$H,4,FALSE)))))
C39: =IF((COUNTA(B10:B36)=0),0,SUM(C10:C38)) -> 0 | D39: =IF((D10)=0," ",SUM(D10:D38)) -> 0 | E39: =IF((E10)=0," ",SUM(E10:E38)) | G39: =IF((G10)=0," ",SUM(G10:G38)/(M2)) -> 0 | I39: =IF((G10)=" ",0,SUM(I10:I38)/$M$2/$E$3) -> 0 | K39: =IF((K10)=0,0,SUM(K10:K38)/(M2)) -> 0 | M39: =IF((L10)=0," ",SUM(M10:M38)/$M$2/$E$3) -> 0 | N39: =IF((M10)=" "," ",SUM(N10:N38)/$E$3) -> 0
B41: QUOTATION RATE | F41: AMOUNT | H41: Prepared by OP: | I41: Roqya
B42: P.P IN DBL | E42: Dollar | F42: =C39+G39+I39+K39+M39+N39+M3 -> 0 | H42: Prepared Date:
B43: SGL SUPPELMENT | E43: Dollar | F43: =D39 -> 0
B44: SUITE SUPPL | E44: Dollar | F44: =E39

Sheet Sites
A1: Site | B1: Price | C1: New Price ( After 1/11/2025)
A2: Citadel | B2: 577.5 | C2: =B2*1.1 -> 635.25
A3: Rifa'i Mosque | B3: 231 | C3: =B3*1.1 -> 254.1
A4: Suhaymi House | B4: 231 | C4: =B4*1.1 -> 254.1
A5: Mohamed Ali Palace | B5: 315 | C5: =B5*1.1 -> 346.5
A6: Senosert Obelisk | B6: 126 | C6: =B6*1.1 -> 138.6
A7: Egyptian Museum | B7: 577.5 | C7: =B7*1.1 -> 635.25
A8: Civilization Museum | B8: 682.5 | C8: =B8*1.1 -> 750.75
A9: Egyptian Museum (Guide) | B9: 78.75 | C9: =B9*1.1 -> 86.625
A10: Islamic Art Museum | B10: 357 | C10: =B10*1.1 -> 392.7
A11: Coptic Museum | B11: 294 | C11: =B11*1.1 -> 323.4
A12: Royal Carriage Museum | B12: 315 | C12: =B12*1.1 -> 346.5
A13: Gayer Anderson Museum | B13: 105 | C13: =B13*1.1 -> 115.5
... A106: High Dam | B106: 210 | C106: =B106*1.1 -> 231
A107: Parasailing | B107: 472.5 | C107: =B107*1.3 -> 614.25
A108: Submarine | B108: 1260 | C108: =B108*1.3 -> 1638
A109: Jet Ski | B109: 262.5 | C109: =B109*1.3 -> 341.25
A110: Banana Boat | B110: 157.5 | C110: =B110*1.3 -> 204.75
A111: Hot Air Balloon | B111: 2625 | C111: =B111*1.3 -> 3412.5
A112: King Tut Mus | B112: 945 | C112: =B112*1.3 -> 1228.5
A113: St Catherine | B113: 525 | C113: =B113*1.3 -> 682.5
A114: Neverland with dinner | B114: 1680 | C114: =B114*1.3 -> 2184
A115: Dolphin | B115: 1974 | C115: =B115*1.3 -> 2566.2
A116: Sea Trip | B116: 1365 | C116: =B116*1.3 -> 1774.5
A117: Neverland without dinner | B117: 1155 | C117: =B117*1.3 -> 1501.5
A118: Quad Bike | B118: 577.5 | C118: =B118*1.3 -> 750.75
... A120: Sharm Museum | B120: 1050 | C120: =B120*1.3 -> 1365
A121: Aqua Park | B121: =50*'Quotation new'!M2 -> 2385 | C121: =B121*1.3 -> 3100.5

Sheet Transfers
A1: Transfer (After 1/6/2025) | B1: Price (Limousine/Hiace) | C1: Price (Coaster) | D1: Price (Bus) | E1: Transfer (After 1/11/2025) | F1: Price (Limousine/Hiace) | G1: Price (Coaster) | H1: Price (Bus) | I1: 1.1
A2: Cairo apt | B2: 1461.075 | C2: 2295.975 | D2: 4591.95 | E2: Cairo apt | F2: =B2*110% -> 1607.1825 | G2: =C2*110% -> 2525.5725 | H2: =D2*110% -> 5051.145
A3: Cairo apt October | B3: 1669.8 | C3: 2643.85 | D3: 5357.275 | E3: Cairo apt October | F3: =B3*110% -> 1836.78 | G3: =C3*110% -> 2908.235 | H3: =D3*110% -> 5893.0025
A4: Sphinx apt | B4: 1913.3125 | C4: 3061.3 | D4: 6122.6 | E4: Sphinx apt | F4: =B4*110% -> 2104.6438 | G4: =C4*110% -> 3367.43 | H4: =D4*110% -> 6734.86
A5: Sphinx apt fd | B5: 3965.775 | C5: 7653.25 | D5: 13775.85 | E5: Sphinx apt fd | F5: =B5*110% -> 4362.3525 | G5: =C5*110% -> 8418.575 | H5: =D5*110% -> 15153.435
A6: New capital apt | B6: 2643.85 | C6: 3339.6 | D6: 6540.05 | E6: New capital apt | F6: =B6*110% -> 2908.235 | G6: =C6*110% -> 3673.56 | H6: =D6*110% -> 7194.055
A7: New capital apt fd | B7: 5218.125 | C7: 9462.2 | D7: 14193.3 | E7: New capital apt fd | F7: =B7*110% -> 5739.9375 | G7: =C7*110% -> 10408.42 | H7: =D7*110% -> 15612.63
A8: Cairo hd | B8: 1669.8 | C8: 3061.3 | D8: 5566 | E8: Cairo hd | F8: =B8*110% -> 1836.78 | G8: =C8*110% -> 3367.43 | H8: =D8*110% -> 6122.6
A9: Cairo fd | B9: 2156.825 | C9: 3826.625 | D9: 8001.125 | E9: Cairo fd | F9: =B9*110% -> 2372.5075 | G9: =C9*110% -> 4209.2875 | H9: =D9*110% -> 8801.2375
A10: Cairo fd October | B10: 2365.55 | C10: 4313.65 | D10: 8696.875 | E10: Cairo fd October | F10: =B10*110% -> 2602.105 | G10: =C10*110% -> 4745.015 | H10: =D10*110% -> 9566.5625
A11: Cairo apt + fd | B11: 3478.75 | C11: 6261.75 | D11: 12940.95 | E11: Cairo apt + fd | F11: =B11*110% -> 3826.625 | G11: =C11*110% -> 6887.925 | H11: =D11*110% -> 14235.045
A12: Cairo night | B12: 1808.95 | C12: 3826.625 | D12: 7653.25 | E12: Cairo night | F12: =B12*110% -> 1989.845 | G12: =C12*110% -> 4209.2875 | H12: =D12*110% -> 8418.575
A13: Cairo open day | B13: 4731.1 | C13: 8279.425 | D13: 14193.3 | E13: Cairo open day | F13: =B13*110% -> 5204.21 | G13: =C13*110% -> 9107.3675 | H13: =D13*110% -> 15612.63
... A33: Sharm Trips | B33: 0 | C33: 0 | D33: 0 | E33: Sharm Trips | F33: =B33*110% -> 0 | G33: =C33*110% -> 0 | H33: =D33*110% -> 0
A34: Dep SSH | B34: 931.04 | C34: 1520.2137 | D34: 3469.5788 | E34: Dep SSH | F34: =B34*130% -> 1210.352 | G34: =C34*130% -> 1976.2779 | H34: =D34*130% -> 4510.4524
A35: Arr SSH | B35: 981.95625 | C35: 1542.035 | D35: 3513.2213 | E35: Arr SSH | F35: =B35*130% -> 1276.5431 | G35: =C35*130% -> 2004.6455 | H35: =D35*130% -> 4567.1876
A36: Transfer Hotel SSH | B36: 771.0175 | C36: 1265.6325 | D36: 2836.7625 | E36: Transfer Hotel SSH | F36: =B36*130% -> 1002.3228 | G36: =C36*130% -> 1645.3222 | H36: =D36*130% -> 3687.7913
A37: Dep / Arr Apt SSH ( Dahab ) | B37: 2313.0525 | C37: 4087.8475 | D37: 6990.0737 | E37: Dep / Arr Apt SSH ( Dahab ) | F37: =B37*130% -> 3006.9682 | G37: =C37*130% -> 5314.2017 | H37: =D37*130% -> 9087.0959
A38: Dep + Arr Apt SSH ( Dahab ) | B38: 3404.115 | C38: 5855.3688 | D38: 10561.485 | E38: Dep + Arr Apt SSH ( Dahab ) | F38: =B38*130% -> 4425.3495 | G38: =C38*130% -> 7611.9794 | H38: =D38*130% -> 13729.93
A39: Dep / Arr Apt SSH ( Nuweiba ) | B39: 3396.8413 | C39: 5768.0837 | D39: 10496.021 | E39: Dep / Arr Apt SSH ( Nuweiba ) | F39: =B39*130% -> 4415.8936 | G39: =C39*130% -> 7498.5089 | H39: =D39*130% -> 13644.828
A40: Dep + Arr Apt SSH ( Nuweiba ) | B40: 5135.2675 | C40: 8786.69 | D40: 15907.691 | E40: Dep + Arr Apt SSH ( Nuweiba ) | F40: =B40*130% -> 6675.8477 | G40: =C40*130% -> 11422.697 | H40: =D40*130% -> 20679.999
A41: Dep / Arr Apt SSH ( Taba ) | B41: 4335.155 | C41: 7055.5375 | D41: 15907.691 | E41: Dep / Arr Apt SSH ( Taba ) | F41: =B41*130% -> 5635.7015 | G41: =C41*130% -> 9172.1987 | H41: =D41*130% -> 20679.999
A42: Dep + Arr Apt SSH ( Taba ) | B42: 6575.47 | C42: 10692.413 | D42: 18977.214 | E42: Dep + Arr Apt SSH ( Taba ) | F42: =B42*130% -> 8548.111 | G42: =C42*130% -> 13900.136 | H42: =D42*130% -> 24670.378
A43: Dep + Arr APT Cairo - SSH | B43: 16256.831 | C43: 20766.556 | D43: 38565.422 | E43: Dep + Arr APT Cairo - SSH | F43: =B43*130% -> 21133.881 | G43: =C43*130% -> 26996.523 | H43: =D43*130% -> 50135.049
A44: Ras Mohamed Half Day ( SSH ) | B44: 2160.3038 | C44: 3324.1038 | D44: 4473.3562 | E44: Ras Mohamed Half Day ( SSH ) | F44: =B44*130% -> 2808.3949 | G44: =C44*130% -> 4321.3349 | H44: =D44*130% -> 5815.3631
A45: Ras Mohamed Full Day ( SSH ) | B45: 2829.4887 | C45: 4226.0487 | D45: 5462.5862 | E45: Ras Mohamed Full Day ( SSH ) | F45: =B45*130% -> 3678.3354 | G45: =C45*130% -> 5493.8634 | H45: =D45*130% -> 7101.3621
... A61: Black Pearl SSH ( 3 Ways ) | B61: 2298.505 | C61: 3956.92 | D61: 9055.8187 | E61: Black Pearl SSH ( 3 Ways ) | F61: =B61*130% -> 2988.0565 | G61: =C61*130% -> 5143.996 | H61: =D61*130% -> 11772.564
B62: 771.0175 | C62: 1323.8225 | D62: 3018.6063 | F62: =B62*130% -> 1002.3228 | G62: =C62*130% -> 1720.9693 | H62: =D62*130% -> 3924.1881
A63: Cairo by Flight / Luxor Flight Dep | B63: 901.945 | C63: 1483.845 | D63: 3433.21 | E63: Cairo by Flight / Luxor Flight Dep | F63: =B63*130% -> 1172.5285 | G63: =C63*130% -> 1928.9985 | H63: =D63*130% -> 4463.173
A64: Cairo by Flight / Luxor Flight Arr | B64: 960.135 | C64: 1520.2137 | D64: 3491.4 | E64: Cairo by Flight / Luxor Flight Arr | F64: =B64*130% -> 1248.1755 | G64: =C64*130% -> 1976.2779 | H64: =D64*130% -> 4538.82
A65: Bedouin Dinner ( SSH ) | B65: 1847.5325 | C65: 2829.4887 | D65: 5986.2963 | E65: Bedouin Dinner ( SSH ) | F65: =B65*130% -> 2401.7922 | G65: =C65*130% -> 3678.3354 | H65: =D65*130% -> 7782.1851
A66: Panorama with Lunch ( SSH ) | B66: 2727.6562 | C66: 3476.8525 | D66: 7499.2362 | E66: Panorama with Lunch ( SSH ) | F66: =B66*130% -> 3545.9531 | G66: =C66*130% -> 4519.9083 | H66: =D66*130% -> 9749.0071
A67: PANORAMA WITH SOHO | B67: 2727.6562 | C67: 3476.8525 | D67: 7499.2362 | E67: PANORAMA WITH SOHO | F67: =B67*130% -> 3545.9531 | G67: =C67*130% -> 4519.9083 | H67: =D67*130% -> 9749.0071
A68: Panorama / SOHO with Dinner | B68: 2160.3038 | C68: 3033.1537 | D68: 6284.52 | E68: Panorama / SOHO with Dinner | F68: =B68*130% -> 2808.3949 | G68: =C68*130% -> 3943.0999 | H68: =D68*130% -> 8169.876
A69: Orientation SSH Full Day ( 9 HRS ) | B69: 2305.7787 | C69: 3942.3725 | D69: 9390.4112 | E69: Orientation SSH Full Day ( 9 HRS ) | F69: =B69*130% -> 2997.5124 | G69: =C69*130% -> 5125.0842 | H69: =D69*130% -> 12207.535
A70: Orientation SSH Half Day ( 6 HRS ) | B70: 1527.4875 | C70: 2618.55 | D70: 6277.2463 | E70: Orientation SSH Half Day ( 6 HRS ) | F70: =B70*130% -> 1985.7338 | G70: =C70*130% -> 3404.115 | H70: =D70*130% -> 8160.4201
A71: Orientation SSH ( 3 HRS ) | B71: 792.83875 | C71: 1331.0963 | D71: 3142.26 | E71: Orientation SSH ( 3 HRS ) | F71: =B71*130% -> 1030.6904 | G71: =C71*130% -> 1730.4251 | H71: =D71*130% -> 4084.938
A72: Orientation Dahab Full Day | B72: 3549.59 | C72: 6189.9612 | D72: 11027.005 | E72: Orientation Dahab Full Day | F72: =B72*130% -> 4614.467 | G72: =C72*130% -> 8046.9496 | H72: =D72*130% -> 14335.106
A73: Orientation Dahab Half Day | B73: 2451.2537 | C73: 4189.68 | D73: 7346.4875 | E73: Orientation Dahab Half Day | F73: =B73*130% -> 3186.6299 | G73: =C73*130% -> 5446.584 | H73: =D73*130% -> 9550.4338
A74: Panorama - Dahab (Vehicle From Dahab) | B74: 1592.9512 | C74: 0 | D74: 0 | E74: Panorama - Dahab (Vehicle From Dahab) | F74: =B74*130% -> 2070.8366 | G74: =C74*130% -> 0 | H74: =D74*130% -> 0
...

Sheet Quotation
C2: Group Ref. No.: | I2: Arr. Date:(dd/mmm/yy) | J2: 45509 | L2: Exchange rate: | M2: 47.7 | N2: EGP
C3: # PAX of Group: | E3: 1 | I3: Dep. Date:(dd/mmm/yy) | J3: 45513 | L3: Estimate Profit: | N3: EURO
B4: EGYPT TOP LIGHT QUOTATION
B6: ACCOMMODATION | F6: SITES/TRIPS | H6: TRANSFERS | J6: MEALS | L6: SERVICES
B7: NIGHTS | C7: Rate | F7: Items | G7: Rate | H7: Items | I7: Rate | J7: Items | K7: Rate | L7: Items | M7: Rate
C8: in DBL | D8: S. Sup. | E8: SUITE . Sup.
C9: USD | D9: USD | E9: USD | G9: LE | I9: LE | K9: LE | M9: LE | N9: USD
D10: =IF(C10="","",C10*0.7) | G10: =IF(F10=""," ",IF(J$2>=DATE(2024,11,1),VLOOKUP(F10,Sites!$A:$B,3,FALSE),VLOOKUP(F10,Sites!$A:$A,2,FALSE))) | I10: =IF(H10="", "", IF(E$3<=7, VLOOKUP(H10, Transfers!$A:$D, 2, FALSE), IF(E$3<=15, VLOOKUP(H10, Transfers!$A:$D, 3, FALSE), VLOOKUP(H10, Transfers!$A:$D, 4, FALSE)))) | L10: Guide | M10: =(J3-J2)*1200 -> 4800
D11: =IF(C11="","",C11*0.7) | G11: =IF(F11=""," ",IF(J$2>=DATE(2024,11,1),VLOOKUP(F11,Sites!$A:$B,3,FALSE),VLOOKUP(F11,Sites!$A:$A,2,FALSE))) | I11: =IF(H11="", "", IF(E$3<=7, VLOOKUP(H11, Transfers!$A:$D, 2, FALSE), IF(E$3<=15, VLOOKUP(H11, Transfers!$A:$D, 3, FALSE), VLOOKUP(H11, Transfers!$A:$D, 4, FALSE)))) | L11: Rep | M11: =(J3-J2)*200 -> 800
D12: =IF(C12="","",C12*0.7) | G12: =IF(F12=""," ",IF(J$2>=DATE(2024,11,1),VLOOKUP(F12,Sites!$A:$B,3,FALSE),VLOOKUP(F12,Sites!$A:$A,2,FALSE))) | I12: =IF(H12="", "", IF(E$3<=7, VLOOKUP(H12, Transfers!$A:$D, 2, FALSE), IF(E$3<=15, VLOOKUP(H12, Transfers!$A:$D, 3, FALSE), VLOOKUP(H12, Transfers!$A:$D, 4, FALSE))))
D13: =IF(C13="","",C13*0.7) | G13: =IF(F13=""," ",IF(J$2>=DATE(2024,11,1),VLOOKUP(F13,Sites!$A:$B,3,FALSE),VLOOKUP(F13,Sites!$A:$A,2,FALSE))) | I13: =IF(H13="", "", IF(E$3<=7, VLOOKUP(H13, Transfers!$A:$D, 2, FALSE), IF(E$3<=15, VLOOKUP(H13, Transfers!$A:$D, 3, FALSE), VLOOKUP(H13, Transfers!$A:$D, 4, FALSE))))
D14: =IF(C14="","",C14*0.7) | G14: =IF(F14=""," ",IF(J$2>=DATE(2024,11,1),VLOOKUP(F14,Sites!$A:$B,3,FALSE),VLOOKUP(F14,Sites!$A:$A,2,FALSE))) | I14: =IF(H14="", "", IF(E$3<=7, VLOOKUP(H14, Transfers!$A:$D, 2, FALSE), IF(E$3<=15, VLOOKUP(H14, Transfers!$A:$D, 3, FALSE), VLOOKUP(H14, Transfers!$A:$D, 4, FALSE))))
D15: =IF(C15="","",C15*0.7) | G15: =IF(F15=""," ",IF(J$2>=DATE(2024,11,1),VLOOKUP(F15,Sites!$A:$B,3,FALSE),VLOOKUP(F15,Sites!$A:$A,2,FALSE))) | I15: =IF(H15="", "", IF(E$3<=7, VLOOKUP(H15, Transfers!$A:$D, 2, FALSE), IF(E$3<=15, VLOOKUP(H15, Transfers!$A:$D, 3, FALSE), VLOOKUP(H15, Transfers!$A:$D, 4, FALSE))))
D16: =IF(C16="","",C16*0.7) | G16: =IF(F16=""," ",IF(J$2>=DATE(2024,11,1),VLOOKUP(F16,Sites!$A:$B,3,FALSE),VLOOKUP(F16,Sites!$A:$A,2,FALSE))) | I16: =IF(H16="", "", IF(E$3<=7, VLOOKUP(H16, Transfers!$A:$D, 2, FALSE), IF(E$3<=15, VLOOKUP(H16, Transfers!$A:$D, 3, FALSE), VLOOKUP(H16, Transfers!$A:$D, 4, FALSE))))
G17: =IF(F17=""," ",IF(J$2>=DATE(2024,11,1),VLOOKUP(F17,Sites!$A:$B,3,FALSE),VLOOKUP(F17,Sites!$A:$A,2,FALSE))) | I17: =IF(H17="", "", IF(E$3<=7, VLOOKUP(H17, Transfers!$A:$D, 2, FALSE), IF(E$3<=15, VLOOKUP(H17, Transfers!$A:$D, 3, FALSE), VLOOKUP(H17, Transfers!$A:$D, 4, FALSE))))
G18: =IF(F18=""," ",IF(J$2>=DATE(2024,11,1),VLOOKUP(F18,Sites!$A:$B,3,FALSE),VLOOKUP(F18,Sites!$A:$A,2,FALSE))) | I18: =IF(H18="", "", IF(E$3<=7, VLOOKUP(H18, Transfers!$A:$D, 2, FALSE), IF(E$3<=15, VLOOKUP(H18, Transfers!$A:$D, 3, FALSE), VLOOKUP(H18, Transfers!$A:$D, 4, FALSE))))
G19: =IF(F19=""," ",IF(J$2>=DATE(2024,11,1),VLOOKUP(F19,Sites!$A:$B,3,FALSE),VLOOKUP(F19,Sites!$A:$A,2,FALSE))) | I19: =IF(H19="", "", IF(E$3<=7, VLOOKUP(H19, Transfers!$A:$D, 2, FALSE), IF(E$3<=15, VLOOKUP(H19, Transfers!$A:$D, 3, FALSE), VLOOKUP(H19, Transfers!$A:$D, 4, FALSE))))
G20: =IF(F20=""," ",IF(J$2>=DATE(2024,11,1),VLOOKUP(F20,Sites!$A:$B,3,FALSE),VLOOKUP(F20,Sites!$A:$A,2,FALSE))) | I20: =IF(H20="", "", IF(E$3<=7, VLOOKUP(H20, Transfers!$A:$D, 2, FALSE), IF(E$3<=15, VLOOKUP(H20, Transfers!$A:$D, 3, FALSE), VLOOKUP(H20, Transfers!$A:$D, 4, FALSE))))
G21: =IF(F21=""," ",IF(J$2>=DATE(2024,11,1),VLOOKUP(F21,Sites!$A:$B,3,FALSE),VLOOKUP(F21,Sites!$A:$A,2,FALSE))) | I21: =IF(H21="", "", IF(E$3<=7, VLOOKUP(H21, Transfers!$A:$D, 2, FALSE), IF(E$3<=15, VLOOKUP(H21, Transfers!$A:$D, 3, FALSE), VLOOKUP(H21, Transfers!$A:$D, 4, FALSE))))
G22: =IF(F22=""," ",IF(J$2>=DATE(2024,11,1),VLOOKUP(F22,Sites!$A:$B,3,FALSE),VLOOKUP(F22,Sites!$A:$A,2,FALSE))) | I22: =IF(H22="", "", IF(E$3<=7, VLOOKUP(H22, Transfers!$A:$D, 2, FALSE), IF(E$3<=15, VLOOKUP(H22, Transfers!$A:$D, 3, FALSE), VLOOKUP(H22, Transfers!$A:$D, 4, FALSE))))
G23: =IF(F23=""," ",IF(J$2>=DATE(2024,11,1),VLOOKUP(F23,Sites!$A:$B,3,FALSE),VLOOKUP(F23,Sites!$A:$A,2,FALSE))) | I23: =IF(H23="", "", IF(E$3<=7, VLOOKUP(H23, Transfers!$A:$D, 2, FALSE), IF(E$3<=15, VLOOKUP(H23, Transfers!$A:$D, 3, FALSE), VLOOKUP(H23, Transfers!$A:$D, 4, FALSE))))
G24: =IF(F24=""," ",IF(J$2>=DATE(2024,11,1),VLOOKUP(F24,Sites!$A:$B,3,FALSE),VLOOKUP(F24,Sites!$A:$A,2,FALSE))) | I24: =IF(H24="", "", IF(E$3<=7, VLOOKUP(H24, Transfers!$A:$D, 2, FALSE), IF(E$3<=15, VLOOKUP(H24, Transfers!$A:$D, 3, FALSE), VLOOKUP(H24, Transfers!$A:$D, 4, FALSE))))
G25: =IF(F25=""," ",IF(J$2>=DATE(2024,11,1),VLOOKUP(F25,Sites!$A:$B,3,FALSE),VLOOKUP(F25,Sites!$A:$A,2,FALSE))) | I25: =IF(H25="", "", IF(E$3<=7, VLOOKUP(H25, Transfers!$A:$D, 2, FALSE), IF(E$3<=15, VLOOKUP(H25, Transfers!$A:$D, 3, FALSE), VLOOKUP(H25, Transfers!$A:$D, 4, FALSE))))
G26: =IF(F26=""," ",IF(J$2>=DATE(2024,11,1),VLOOKUP(F26,Sites!$A:$B,3,FALSE),VLOOKUP(F26,Sites!$A:$A,2,FALSE))) | I26: =IF(H26="", "", IF(E$3<=7, VLOOKUP(H26, Transfers!$A:$D, 2, FALSE), IF(E$3<=15, VLOOKUP(H26, Transfers!$A:$D, 3, FALSE), VLOOKUP(H26, Transfers!$A:$D, 4, FALSE))))
G27: =IF(F27=""," ",IF(J$2>=DATE(2024,11,1),VLOOKUP(F27,Sites!$A:$B,3,FALSE),VLOOKUP(F27,Sites!$A:$A,2,FALSE))) | I27: =IF(H27="", "", IF(E$3<=7, VLOOKUP(H27, Transfers!$A:$D, 2, FALSE), IF(E$3<=15, VLOOKUP(H27, Transfers!$A:$D, 3, FALSE), VLOOKUP(H27, Transfers!$A:$D, 4, FALSE))))
G28: =IF(F28=""," ",IF(J$2>=DATE(2024,11,1),VLOOKUP(F28,Sites!$A:$B,3,FALSE),VLOOKUP(F28,Sites!$A:$A,2,FALSE))) | I28: =IF(H28="", "", IF(E$3<=7, VLOOKUP(H28, Transfers!$A:$D, 2, FALSE), IF(E$3<=15, VLOOKUP(H28, Transfers!$A:$D, 3, FALSE), VLOOKUP(H28, Transfers!$A:$D, 4, FALSE))))
... G38: =IF(F38=""," ",IF(J$2>=DATE(2024,11,1),VLOOKUP(F38,Sites!$A:$B,3,FALSE),VLOOKUP(F38,Sites!$A:$A,2,FALSE))) | I38: =IF(H38="", "", IF(E$3<=7, VLOOKUP(H38, Transfers!$A:$D, 2, FALSE), IF(E$3<=15, VLOOKUP(H38, Transfers!$A:$D, 3, FALSE), VLOOKUP(H38, Transfers!$A:$D, 4, FALSE))))
C39: =IF((COUNTA(B10:B36)=0),0,SUM(C10:C38)) -> 0 | D39: =IF((D10)=0," ",SUM(D10:D38)) -> 0 | E39: =IF((E10)=0," ",SUM(E10:E38)) | G39: =IF((G10)=0," ",SUM(G10:G38)/(M2)) -> 0 | I39: =IF((G10)=" ",0,SUM(I10:I38)/$M$2/$E$3) -> 0 | K39: =IF((K10)=0,0,SUM(K10:K38)/(M2)) -> 0 | M39: =IF((L10)=0," ",SUM(M10:M38)/$M$2/$E$3) -> 117.40042 | N39: =IF((M10)=" "," ",SUM(N10:N38)/$E$3) -> 0
B41: QUOTATION RATE | F41: AMOUNT | H41: Prepared by OP: | I41: Roqya
B42: P.P IN DBL | E42: Dollar | F42: =C39+G39+I39+K39+M39+N39+M3 -> 117.40042 | H42: Prepared Date:
B43: SGL SUPPELMENT | E43: Dollar | F43: =D39 -> 0
B44: SUITE SUPPL | E44: Dollar | F44: =E39
